<?xml version="1.0" ?>
<!-- =================================================================================== -->
<!-- |    This document was autogenerated by xacro from /home/hgj/arm_ws/src/-ros_gazebo_car_camera_yolo/mbot/mbot_description/urdf/xacro/gazebo/mbot_whole.xacro | -->
<!-- |    EDITING THIS FILE BY HAND IS NOT RECOMMENDED                                 | -->
<!-- =================================================================================== -->
<robot name="robot">
    <!-- Defining the colors used in this robot -->
    <material name="yellow">
        <color rgba="1 0.4 0 1" />
    </material>
    <material name="black">
        <color rgba="0 0 0 0.95" />
    </material>
    <material name="gray">
        <color rgba="0.75 0.75 0.75 1" />
    </material>
    <!-- Defining the colors used in this robot -->
    <material name="Brown">
        <color rgba="0.65 0.16 0.16 1" />
    </material>
    <material name="Black">
        <color rgba="0 0 0 1" />
    </material>
    <material name="White">
        <color rgba="1 1 1 1" />
    </material>
    <material name="Blue">
        <color rgba="0 0 1 1" />
    </material>
    <material name="Red">
        <color rgba="1 0 0 1" />
    </material>
    <!-- ///////////////////////////////////////   bottom_joint   ////////////////////////////////////////// -->
    <!-- <joint name="bottom_joint" type="fixed">
        <origin xyz="0 0 0" rpy="0 0 0" />
        <parent link="camera_link"/>
        <child link="bottom_link"/>
    </joint>

    <link name="bottom_link">
        <visual>
              <origin xyz=" 0 0 -0.02"  rpy="0 0 0"/>
                  <geometry>
                       <box size="1 1 0.02" />
                  </geometry>
              <material name="Brown" />
        </visual>
        <collision>
            <origin xyz=" 0 0 -0.02"  rpy="0 0 0"/>
            <geometry>
                <box size="1 1 0.02" />
            </geometry>
        </collision>
        <xacro:inertial_matrix mass="500"/>
    </link> -->
    <!-- /////////////////////////////////////   BASE LINK    ////////////////////////////////////////////// -->
    <joint name="connect_joint" type="fixed">
        <origin rpy="0 0 0" xyz="0 0 0.11" />
        <parent link="base_link" />
        <child link="connect_link" />
    </joint>
    <link name="connect_link">
        <!-- <visual>
            <origin rpy="0 0 3.14" xyz="0 0 0" />
            <geometry>
                <cylinder length="0.16" radius="0.2" />
            </geometry>
            <material name="yellow" />
        </visual>
        <collision>
            <origin rpy="0 0 0" xyz=" 0 0 0" />
            <geometry>
                <cylinder length="0.16" radius="0.2" />
            </geometry>
        </collision>
        <inertial>
            <mass value="20" />
            <inertia ixx="0.24266666666666672" ixy="0" ixz="0" iyy="0.24266666666666672" iyz="0" izz="0.4" />
            <origin xyz="0 0 0" rpy="0 0 0" />
        </inertial> -->
    </link>
    <joint name="arm_base_joint" type="fixed">
        <parent link="connect_link" />
        <child link="arm_base_link" />
        <oFrigin rpy="0 0 0" xyz=" 0 0" />
    </joint>
    <link name="arm_base_link">
        <visual>
            <origin rpy="0 0 0" xyz="0 0 0" />
            <geometry>
                <box size="0.02 0.02 0.03" />
            </geometry>
            <material name="White" />
        </visual>
        <collision>
            <origin rpy="0 0 0" xyz="0 0 0" />
            <geometry>
                <box size="0.02 0.02 0.03" />
            </geometry>
        </collision>
        <inertial>
            <mass value="0.12" />
            <inertia ixx="1.0" ixy="0.1" ixz="0.1" iyy="0.5" iyz="0.1" izz="1.0" />
            <origin xyz="0 0 0" rpy="0 0 0" />
        </inertial>
    </link>
    <joint name="joint1" type="revolute">
        <parent link="arm_base_link" />
        <child link="link1" />
        <origin rpy="0 1.570795 0" xyz="0 0 0.02" />
        <axis xyz="-1 0 0" />
        <limit effort="300" lower="-2.96" upper="2.96" velocity="1" />
        <dynamics damping="50" friction="1" />
    </joint>
    <!-- /////////////////////////////////////   LINK1  ////////////////////////////////////////////// -->
    <link name="link1">
        <visual>
            <origin rpy="0 1.570795 0" xyz="-0.05 0 0" />
            <geometry>
                <cylinder length="0.1" radius="0.03" />
            </geometry>
            <material name="Blue" />
        </visual>
        <collision>
            <origin rpy="0 1.570795 0" xyz="-0.05 0 0" />
            <geometry>
                <cylinder length="0.1" radius="0.03" />
            </geometry>
        </collision>
        <inertial>
            <mass value="0.1" />
            <inertia ixx="1.0" ixy="0.1" ixz="0.1" iyy="0.5" iyz="0.1" izz="1.0" />
            <origin xyz="0 0 0" rpy="0 0 0" />
        </inertial>
    </link>
    <joint name="joint2" type="revolute">
        <parent link="link1" />
        <child link="link2" />
        <origin rpy="-1.570795 0 1.570795" xyz="-0.1 0 0.0" />
        <axis xyz="1 0 0" />
        <limit effort="300" lower="-2.35" upper="2.35" velocity="1" />
        <dynamics damping="50" friction="1" />
    </joint>
    <!-- ///////////////////////////////////////   LINK2  ////////////////////////////////////////////// -->
    <link name="link2">
        <visual>
            <origin rpy="0 0 0" xyz="0 0 0.07" />
            <geometry>
                <cylinder length="0.14" radius="0.03" />
            </geometry>
            <material name="White" />
        </visual>
        <collision>
            <origin rpy="0 0 0" xyz="0 0 0.07" />
            <geometry>
                <cylinder length="0.14" radius="0.03" />
            </geometry>
        </collision>
        <inertial>
            <mass value="0.1" />
            <inertia ixx="1.0" ixy="0.1" ixz="0.1" iyy="0.5" iyz="0.1" izz="1.0" />
            <origin xyz="0 0 0" rpy="0 0 0" />
        </inertial>
    </link>
    <joint name="joint3" type="revolute">
        <parent link="link2" />
        <child link="link3" />
        <origin rpy="0 3.14159 0" xyz="0 0 0.14" />
        <axis xyz="-1 0 0" />
        <limit effort="300" lower="-2.62" upper="2.62" velocity="1" />
        <dynamics damping="50" friction="1" />
    </joint>
    <!-- /////////////////////////////////   LINK3  ///////////////////////////////////////////////////// -->
    <link name="link3">
        <visual>
            <origin rpy="0 0 0" xyz="0 0 -0.11" />
            <geometry>
                <cylinder length="0.22" radius="0.03" />
            </geometry>
            <material name="Blue" />
        </visual>
        <collision>
            <origin rpy="0 0 0" xyz="0 0 -0.11" />
            <geometry>
                <cylinder length="0.22" radius="0.03" />
            </geometry>
        </collision>
        <inertial>
            <mass value="0.1" />
            <inertia ixx="1.0" ixy="0.1" ixz="0.1" iyy="0.5" iyz="0.1" izz="1.0" />
            <origin xyz="0 0 0" rpy="0 0 0" />
        </inertial>
    </link>
    <joint name="joint4" type="revolute">
        <parent link="link3" />
        <child link="link4" />
        <origin rpy="0 1.570795 3.14159" xyz="0.0 0.0 -0.22" />
        <axis xyz="1 0 0" />
        <limit effort="300" lower="-2.62" upper="2.62" velocity="1" />
        <dynamics damping="50" friction="1" />
    </joint>
    <!-- ///////////////////////////////////   LINK4  //////////////////////////////////////////////// -->
    <link name="link4">
        <visual>
            <origin rpy="0 1.570795 0" xyz="0.03 0 0" />
            <geometry>
                <cylinder length="0.06" radius="0.025" />
            </geometry>
            <material name="Black" />
        </visual>
        <collision>
            <origin rpy="0 1.570795 0" xyz="0.03 0 0" />
            <geometry>
                <cylinder length="0.06" radius="0.025" />
            </geometry>
        </collision>
        <inertial>
            <mass value="0.1" />
            <inertia ixx="1.0" ixy="0.1" ixz="0.1" iyy="0.5" iyz="0.1" izz="1.0" />
            <origin xyz="0 0 0" rpy="0 0 0" />
        </inertial>
    </link>
    <joint name="joint5" type="revolute">
        <parent link="link4" />
        <child link="link5" />
        <origin rpy="0 1.570795 0" xyz="0.06 0.0 0.0" />
        <axis xyz="1 0 0" />
        <limit effort="300" lower="-2.62" upper="2.62" velocity="1" />
        <dynamics damping="50" friction="1" />
    </joint>
    <!-- //////////////////////////////////   LINK5  ///////////////////////////////////////////////// -->
    <link name="link5">
        <visual>
            <origin rpy="0 0 0" xyz="0 0 0.03" />
            <geometry>
                <cylinder length="0.06" radius="0.03" />
            </geometry>
            <material name="White" />
        </visual>
        <collision>
            <origin rpy="0 0 0" xyz="0 0 0.03 " />
            <geometry>
                <cylinder length="0.06" radius="0.03" />
            </geometry>
        </collision>
        <inertial>
            <mass value="0.1" />
            <inertia ixx="1.0" ixy="0.1" ixz="0.1" iyy="0.5" iyz="0.1" izz="1.0" />
            <origin xyz="0 0 0" rpy="0 0 0" />
        </inertial>
    </link>
    <joint name="joint6" type="revolute">
        <parent link="link5" />
        <child link="link6" />
        <origin rpy="4.712384999999999 -1.570795 0" xyz="0 0 0.06" />
        <axis xyz="1 0 0" />
        <limit effort="300" lower="-6.28" upper="6.28" velocity="1" />
        <dynamics damping="50" friction="1" />
    </joint>
    <!-- ////////////////////////////////   LINK6  ///////////////////////////////////////////////// -->
    <link name="link6">
        <visual>
            <origin rpy="0 1.570795 0" xyz="0.01 0 0 " />
            <geometry>
                <cylinder length="0.02" radius="0.04" />
            </geometry>
            <material name="Blue" />
        </visual>
        <collision>
            <origin rpy="0 1.570795 0" xyz="0.01 0 0" />
            <geometry>
                <cylinder length="0.02" radius="0.04" />
            </geometry>
        </collision>
        <inertial>
            <mass value="0.1" />
            <inertia ixx="1.0" ixy="0.1" ixz="0.1" iyy="0.5" iyz="0.1" izz="1.0" />
            <origin xyz="0 0 0" rpy="0 0 0" />
        </inertial>
    </link>
    <joint name="finger_joint1" type="prismatic">
        <parent link="link6" />
        <child link="gripper_finger_link1" />
        <origin xyz="0.0 0 0" />
        <axis xyz="0 1 0" />
        <limit effort="100" lower="0" upper="0.06" velocity="1.0" />
        <dynamics damping="50" friction="1" />
    </joint>
    <!-- //////////////////////////////////////   gripper   ////////////////////////////////////////////// -->
    <!-- LEFT GRIPPER AFT LINK -->
    <link name="gripper_finger_link1">
        <visual>
            <origin xyz="0.04 -0.03 0" />
            <geometry>
                <box size="0.08 0.01 0.01" />
            </geometry>
            <material name="White" />
        </visual>
        <inertial>
            <mass value="0.1" />
            <inertia ixx="1.0" ixy="0.1" ixz="0.1" iyy="0.5" iyz="0.1" izz="1.0" />
        </inertial>
    </link>
    <joint name="finger_joint2" type="fixed">
        <parent link="link6" />
        <child link="gripper_finger_link2" />
        <origin xyz="0.0 0 0" />
    </joint>
    <!-- RIGHT GRIPPER AFT LINK -->
    <link name="gripper_finger_link2">
        <visual>
            <origin xyz="0.04 0.03 0" />
            <geometry>
                <box size="0.08 0.01 0.01" />
            </geometry>
            <material name="White" />
        </visual>
        <inertial>
            <mass value="0.1" />
            <inertia ixx="1.0" ixy="0.1" ixz="0.1" iyy="0.5" iyz="0.1" izz="1.0" />
        </inertial>
    </link>
    <!-- Grasping frame -->
    <link name="grasping_frame" />
    <joint name="grasping_frame_joint" type="fixed">
        <parent link="link6" />
        <child link="grasping_frame" />
        <origin rpy="0 0 0" xyz="0.08 0 0" />
    </joint>
    <!-- /////////////////////////////////   Gazebo   ////////////////////////////////////// -->
    <gazebo reference="bottom_link">
        <material>Gazebo/White</material>
        <plugin name="gazebo_ros_control">
            <robotNamespace>/</robotNamespace>
        </plugin>
    </gazebo>
    <gazebo reference="arm_base_link">
        <material>Gazebo/White</material>
    </gazebo>
    <gazebo reference="link1">
        <material>Gazebo/Blue</material>
    </gazebo>
    <gazebo reference="link2">
        <material>Gazebo/White</material>
    </gazebo>
    <gazebo reference="link3">
        <material>Gazebo/Blue</material>
    </gazebo>
    <gazebo reference="link4">
        <material>Gazebo/Black</material>
    </gazebo>
    <gazebo reference="link5">
        <material>Gazebo/White</material>
    </gazebo>
    <gazebo reference="link6">
        <material>Gazebo/Blue</material>
    </gazebo>
    <gazebo reference="gripper_finger_link1">
        <material>Gazebo/White</material>
    </gazebo>
    <gazebo reference="gripper_finger_link2">
        <material>Gazebo/White</material>
    </gazebo>
    <transmission name="tran1">
        <type>transmission_interface/SimpleTransmission</type>
        <joint name="joint1">
            <hardwareInterface>hardware_interface/PositionJointInterface</hardwareInterface>
        </joint>
        <actuator name="motor1">
            <hardwareInterface>hardware_interface/PositionJointInterface</hardwareInterface>
            <mechanicalReduction>1</mechanicalReduction>
        </actuator>
    </transmission>
    <transmission name="tran1">
        <type>transmission_interface/SimpleTransmission</type>
        <joint name="joint2">
            <hardwareInterface>hardware_interface/PositionJointInterface</hardwareInterface>
        </joint>
        <actuator name="motor1">
            <hardwareInterface>hardware_interface/PositionJointInterface</hardwareInterface>
            <mechanicalReduction>1</mechanicalReduction>
        </actuator>
    </transmission>
    <transmission name="tran1">
        <type>transmission_interface/SimpleTransmission</type>
        <joint name="joint3">
            <hardwareInterface>hardware_interface/PositionJointInterface</hardwareInterface>
        </joint>
        <actuator name="motor1">
            <hardwareInterface>hardware_interface/PositionJointInterface</hardwareInterface>
            <mechanicalReduction>1</mechanicalReduction>
        </actuator>
    </transmission>
    <transmission name="tran1">
        <type>transmission_interface/SimpleTransmission</type>
        <joint name="joint4">
            <hardwareInterface>hardware_interface/PositionJointInterface</hardwareInterface>
        </joint>
        <actuator name="motor1">
            <hardwareInterface>hardware_interface/PositionJointInterface</hardwareInterface>
            <mechanicalReduction>1</mechanicalReduction>
        </actuator>
    </transmission>
    <transmission name="tran1">
        <type>transmission_interface/SimpleTransmission</type>
        <joint name="joint5">
            <hardwareInterface>hardware_interface/PositionJointInterface</hardwareInterface>
        </joint>
        <actuator name="motor1">
            <hardwareInterface>hardware_interface/PositionJointInterface</hardwareInterface>
            <mechanicalReduction>1</mechanicalReduction>
        </actuator>
    </transmission>
    <transmission name="tran1">
        <type>transmission_interface/SimpleTransmission</type>
        <joint name="joint6">
            <hardwareInterface>hardware_interface/PositionJointInterface</hardwareInterface>
        </joint>
        <actuator name="motor1">
            <hardwareInterface>hardware_interface/PositionJointInterface</hardwareInterface>
            <mechanicalReduction>1</mechanicalReduction>
        </actuator>
    </transmission>
    <transmission name="tran1">
        <type>transmission_interface/SimpleTransmission</type>
        <joint name="finger_joint1">
            <hardwareInterface>hardware_interface/PositionJointInterface</hardwareInterface>
        </joint>
        <actuator name="motor1">
            <hardwareInterface>hardware_interface/PositionJointInterface</hardwareInterface>
            <mechanicalReduction>1</mechanicalReduction>
        </actuator>
    </transmission>
    <!-- ros_control plugin -->
    <gazebo>
        <plugin filename="libgazebo_ros_control.so" name="gazebo_ros_control">
            <robotNamespace>/arm</robotNamespace>
        </plugin>
    </gazebo>
    <!-- Camera -->
    <joint name="camera_joint" type="fixed">
        <origin rpy="0 0 0" xyz="0.17 0 0.1" />
        <parent link="base_link" />
        <child link="camera_link" />
    </joint>
    <!-- Create laser reference frame -->
    <link name="camera_link">
        <inertial>
            <mass value="0.1" />
            <origin xyz="0 0 0" rpy="0 0 3.14" />
            <inertia ixx="0.01" ixy="0.0" ixz="0.0" iyy="0.01" iyz="0.0" izz="0.01" />
        </inertial>
        <visual>
            <origin rpy="0 0 0" xyz=" 0 0 0 " />
            <geometry>
                <box size="0.01 0.04 0.04" />
            </geometry>
            <material name="black" />
        </visual>
        <collision>
            <origin rpy="0 0 0" xyz="0.0 0.0 0.0" />
            <geometry>
                <box size="0.01 0.04 0.04" />
            </geometry>
        </collision>
    </link>
    <gazebo reference="camera_link">
        <material>Gazebo/Black</material>
    </gazebo>
    <gazebo reference="camera_link">
        <sensor name="camera_node" type="camera">
            <update_rate>30.0</update_rate>
            <camera name="head">
                <horizontal_fov>1.3962634</horizontal_fov>
                <image>
                    <width>1280</width>
                    <height>720</height>
                    <format>R8G8B8</format>
                </image>
                <clip>
                    <near>0.02</near>
                    <far>300</far>
                </clip>
                <noise>
                    <type>gaussian</type>
                    <mean>0.0</mean>
                    <stddev>0.007</stddev>
                </noise>
            </camera>
            <plugin filename="libgazebo_ros_camera.so" name="gazebo_camera">
                <alwaysOn>true</alwaysOn>
                <updateRate>0.0</updateRate>
                <cameraName>/camera</cameraName>
                <imageTopicName>image_raw</imageTopicName>
                <cameraInfoTopicName>camera_info</cameraInfoTopicName>
                <frameName>camera_link</frameName>
                <hackBaseline>0.07</hackBaseline>
                <distortionK1>0.0</distortionK1>
                <distortionK2>0.0</distortionK2>
                <distortionK3>0.0</distortionK3>
                <distortionT1>0.0</distortionT1>
                <distortionT2>0.0</distortionT2>
            </plugin>
        </sensor>
    </gazebo>
    <link name="base_footprint">
        <visual>
            <origin rpy="0 0 3.14" xyz="0 0 0" />
            <geometry>
                <box size="0.001 0.001 0.001" />
            </geometry>
        </visual>
    </link>
    <gazebo reference="base_footprint">
        <turnGravityOff>false</turnGravityOff>
    </gazebo>
    <joint name="base_footprint_joint" type="fixed">
        <origin rpy="0 0 0" xyz="0 0 0.11" />
        <parent link="base_footprint" />
        <child link="base_link" />
    </joint>
    <link name="base_link">
        <visual>
            <origin rpy="0 0 0" xyz="0 0 0" />
            <geometry>
                <cylinder length="0.16" radius="0.2" />
            </geometry>
            <material name="yellow" />
        </visual>
        <collision>
            <origin rpy="0 0 0" xyz=" 0 0 0" />
            <geometry>
                <cylinder length="0.16" radius="0.2" />
            </geometry>
        </collision>
        <inertial>
            <mass value="20" />
            <inertia ixx="0.24266666666666672" ixy="0" ixz="0" iyy="0.24266666666666672" iyz="0" izz="0.4" />
            <origin xyz="0 0 0" rpy="0 0 0" />
        </inertial>
    </link>
    <gazebo reference="base_link">
        <material>Gazebo/Blue</material>
    </gazebo>
    <joint name="left_wheel_joint" type="continuous">
        <origin rpy="0 0 0" xyz="0 0.19 -0.05" />
        <parent link="base_link" />
        <child link="left_wheel_link" />
        <axis xyz="0 1 0" />
    </joint>
    <link name="left_wheel_link">
        <visual>
            <origin rpy="1.570795 0 0" xyz="0 0 0" />
             <!-- <surface>
                <friction>
                    <ode>
                    <mu>12.0</mu>
                    <mu2>10.0</mu2>
                    </ode>
                </friction>
            </surface> -->
            <geometry>
                <cylinder length="0.025" radius="0.06" />
            </geometry>
            <material name="gray" />
        </visual>
        <collision>
            <origin rpy="1.570795 0 0" xyz="0 0 0" />
            <geometry>
                <cylinder length="0.025" radius="0.06" />
            </geometry>
        </collision>
        <mu1>0.5</mu1>
        <mu2>0.5</mu2>
        <inertial>
            <mass value="2" />
            <inertia ixx="0.0019041666666666666" ixy="0" ixz="0" iyy="0.0019041666666666666" iyz="0" izz="0.0036" />
            <origin xyz="0 0 0" rpy="0 0 0" />
        </inertial>
    </link>
    <gazebo reference="left_wheel_link">
        <material>Gazebo/Gray</material>
    </gazebo>
    <!-- Transmission is important to link the joints and the controller -->
    <transmission name="left_wheel_joint_trans">
        <type>transmission_interface/SimpleTransmission</type>
        <joint name="left_wheel_joint">
            <hardwareInterface>hardware_interface/VelocityJointInterface</hardwareInterface>
        </joint>
        <actuator name="left_wheel_joint_motor">
            <hardwareInterface>hardware_interface/VelocityJointInterface</hardwareInterface>
            <mechanicalReduction>1</mechanicalReduction>
        </actuator>
    </transmission>
    <joint name="right_wheel_joint" type="continuous">
        <origin rpy="0 0 0" xyz="0 -0.19 -0.05" />
        <parent link="base_link" />
        <child link="right_wheel_link" />
        <axis xyz="0 1 0" />
    </joint>
    <link name="right_wheel_link">
        <visual>
            <origin rpy="1.570795 0 0" xyz="0 0 0" />
            <!-- <surface>
                <friction>
                    <ode>
                    <mu>12.0</mu>
                    <mu2>10.0</mu2>
                    </ode>
                </friction>
            </surface> -->
            <geometry>
                <cylinder length="0.025" radius="0.06" />
            </geometry>
            <material name="gray" />
        </visual>
        <collision>
            <origin rpy="1.570795 0 0" xyz="0 0 0" />
            <geometry>
                <cylinder length="0.025" radius="0.06" />
            </geometry>
        </collision>
        <mu1>0.5</mu1>
        <mu2>0.5</mu2>
        <inertial>
            <mass value="2" />
            <inertia ixx="0.0019041666666666666" ixy="0" ixz="0" iyy="0.0019041666666666666" iyz="0" izz="0.0036" />
            <origin xyz="0 0 0" rpy="0 0 0" />
        </inertial>
    </link>
    <gazebo reference="right_wheel_link">
        <material>Gazebo/Gray</material>
    </gazebo>
    <!-- Transmission is important to link the joints and the controller -->
    <transmission name="right_wheel_joint_trans">
        <type>transmission_interface/SimpleTransmission</type>
        <joint name="right_wheel_joint">
            <hardwareInterface>hardware_interface/VelocityJointInterface</hardwareInterface>
        </joint>
        <actuator name="right_wheel_joint_motor">
            <hardwareInterface>hardware_interface/VelocityJointInterface</hardwareInterface>
            <mechanicalReduction>1</mechanicalReduction>
        </actuator>
    </transmission>
    <joint name="front_caster_joint" type="continuous">
        <origin rpy="0 0 0" xyz="-0.18 0 -0.095" />
        <parent link="base_link" />
        <child link="front_caster_link" />
        <axis xyz="0 1 0" />
    </joint>
    <link name="front_caster_link">
        <visual>
            <origin rpy="0 0 0" xyz="0 0 0" />
            <!-- <surface>
                <friction>
                    <ode>
                    <mu>12.0</mu>
                    <mu2>10.0</mu2>
                    </ode>
                </friction>
            </surface> -->
            <geometry>
                <sphere radius="0.015" />
            </geometry>
            <material name="black" />
        </visual>
        <collision>
            <origin rpy="0 0 0" xyz="0 0 0" />
            <geometry>
                <sphere radius="0.015" />
            </geometry>
        </collision>
        <mu1>0.5</mu1>
        <mu2>0.5</mu2>
        <inertial>
            <mass value="0.5" />
            <inertia ixx="4.4999999999999996e-05" ixy="0" ixz="0" iyy="4.4999999999999996e-05" iyz="0" izz="4.4999999999999996e-05" />
            <origin xyz="0 0 0" rpy="0 0 0" />
        </inertial>
    </link>
    <gazebo reference="front_caster_link">
        <material>Gazebo/Black</material>
    </gazebo>
    <joint name="back_caster_joint" type="continuous">
        <origin rpy="0 0 0" xyz="0.18 0 -0.095" />
        <parent link="base_link" />
        <child link="back_caster_link" />
        <axis xyz="0 1 0" />
    </joint>
    <link name="back_caster_link">
        <visual>
            <origin rpy="0 0 0" xyz="0 0 0" />
            <!-- <surface>
                <friction>
                    <ode>
                    <mu>12.0</mu>
                    <mu2>10.0</mu2>
                    </ode>
                </friction>
            </surface> -->
            <geometry>
                <sphere radius="0.015" />
            </geometry>
            <material name="black" />
        </visual>
        <collision>
            <origin rpy="0 0 0" xyz="0 0 0" />
            <geometry>
                <sphere radius="0.015" />
            </geometry>
        </collision>
        <mu1>0.5</mu1>
        <mu2>0.5</mu2>
        <inertial>
            <mass value="0.5" />
            <inertia ixx="4.4999999999999996e-05" ixy="0" ixz="0" iyy="4.4999999999999996e-05" iyz="0" izz="4.4999999999999996e-05" />
            <origin xyz="0 0 0" rpy="0 0 0" />
        </inertial>
    </link>
    <gazebo reference="back_caster_link">
        <material>Gazebo/Black</material>
    </gazebo>
    <!-- controller -->
    <gazebo>
        <plugin filename="libgazebo_ros_diff_drive.so" name="differential_drive_controller">
            <rosDebugLevel>Debug</rosDebugLevel>
            <publishWheelTF>true</publishWheelTF>
            <robotNamespace>/</robotNamespace>
            <publishTf>1</publishTf>
            <publishWheelJointState>true</publishWheelJointState>
            <alwaysOn>true</alwaysOn>
            <updateRate>100.0</updateRate>
            <legacyMode>true</legacyMode>
            <leftJoint>left_wheel_joint</leftJoint>
            <rightJoint>right_wheel_joint</rightJoint>
            <wheelSeparation>0.38</wheelSeparation>
            <wheelDiameter>0.12</wheelDiameter>
            <broadcastTF>1</broadcastTF>
            <wheelTorque>30</wheelTorque>
            <wheelAcceleration>1.8</wheelAcceleration>
            <commandTopic>cmd_vel</commandTopic>
            <odometryFrame>odom</odometryFrame>
            <odometryTopic>odom</odometryTopic>
            <robotBaseFrame>base_footprint</robotBaseFrame>
        </plugin>
    </gazebo>
    <transmission name="trans_front_caster_joint">
        <type>transmission_interface/SimpleTransmission</type>
        <joint name="front_caster_joint">
            <hardwareInterface>hardware_interface/EffortJointInterface</hardwareInterface>
        </joint>
        <actuator name="front_caster_joint_motor">
            <hardwareInterface>hardware_interface/EffortJointInterface</hardwareInterface>
            <mechanicalReduction>1</mechanicalReduction>
        </actuator>
    </transmission>
    <transmission name="trans_back_caster_joint">
        <type>transmission_interface/SimpleTransmission</type>
        <joint name="back_caster_joint">
            <hardwareInterface>hardware_interface/EffortJointInterface</hardwareInterface>
        </joint>
        <actuator name="back_caster_joint_motor">
            <hardwareInterface>hardware_interface/EffortJointInterface</hardwareInterface>
            <mechanicalReduction>1</mechanicalReduction>
        </actuator>
    </transmission>
</robot>
